<?xml version="1.0"?>
<robot name="robotiq_hande_gripper">

  <!-- Links -->
  <link name="robotiq_hande_coupler">
    <visual><geometry>
      <mesh filename="kuka_maniskill_sim/meshes/gripper/io_coupler.dae"/>
    </geometry></visual>
  </link>

  <link name="robotiq_hande_link">
    <visual><geometry>
      <mesh filename="kuka_maniskill_sim/meshes/gripper/hande.dae"/>
    </geometry></visual>
  </link>

  <link name="robotiq_hande_left_finger">
    <visual><geometry>
      <mesh filename="kuka_maniskill_sim/meshes/gripper/finger.dae"/>
    </geometry></visual>
  </link>

  <link name="robotiq_hande_right_finger">
    <visual>
      <origin rpy="0 0 3.14159265"/>
      <geometry>
        <mesh filename="kuka_maniskill_sim/meshes/gripper/finger.dae"/>
      </geometry>
    </visual>
  </link>

  <link name="robotiq_hande_end"/>

  <!-- Joints -->
  <!-- weld the coupler to whatever link you attach later -->
  <joint name="robotiq_hande_base_joint" type="fixed">
    <origin xyz="0 0 0.011" rpy="0 0 0"/>
    <parent link="robotiq_hande_coupler"/>
    <child  link="robotiq_hande_link"/>
  </joint>

  <joint name="robotiq_hande_left_finger_joint" type="prismatic">
    <origin xyz="0 0 0.099" rpy="0 0 0"/>
    <parent link="robotiq_hande_link"/>
    <child  link="robotiq_hande_left_finger"/>
    <axis xyz="1 0 0"/>
    <limit effort="130" lower="0.0" upper="0.03" velocity="0.15"/>
  </joint>

  <joint name="robotiq_hande_right_finger_joint" type="prismatic">
    <origin xyz="0 0 0.099" rpy="0 0 0"/>
    <parent link="robotiq_hande_link"/>
    <child  link="robotiq_hande_right_finger"/>
    <axis xyz="-1 0 0"/>
    <limit effort="130" lower="0.0" upper="0.03" velocity="0.15"/>
  </joint>

  <joint name="robotiq_hande_end_joint" type="fixed">
    <origin xyz="0 0 0.1455" rpy="0 0 0"/>
    <parent link="robotiq_hande_link"/>
    <child  link="robotiq_hande_end"/>
  </joint>

</robot>
